WARNING:googleapiclient.discovery_cache:file_cache is unavailable when using oauth2client >= 4.0.0 or google-auth
Traceback (most recent call last):
  File "C:\YOLOv5\yolov5\lib\site-packages\googleapiclient\discovery_cache\file_cache.py", line 33, in <module>
    from oauth2client.contrib.locked_file import LockedFile
ModuleNotFoundError: No module named 'oauth2client.contrib.locked_file'

During handling of the above exception, another exception occurred:

Traceback (most recent call last):
  File "C:\YOLOv5\yolov5\lib\site-packages\googleapiclient\discovery_cache\file_cache.py", line 37, in <module>
    from oauth2client.locked_file import LockedFile
ModuleNotFoundError: No module named 'oauth2client.locked_file'

During handling of the above exception, another exception occurred:

Traceback (most recent call last):
  File "C:\YOLOv5\yolov5\lib\site-packages\googleapiclient\discovery_cache\__init__.py", line 44, in autodetect
    from . import file_cache
  File "C:\YOLOv5\yolov5\lib\site-packages\googleapiclient\discovery_cache\file_cache.py", line 41, in <module>
    "file_cache is unavailable when using oauth2client >= 4.0.0 or google-auth"
ImportError: file_cache is unavailable when using oauth2client >= 4.0.0 or google-auth
DEBUG:googleapiclient.discovery:URL being requested: GET https://www.googleapis.com/discovery/v1/apis/gmail/v1/rest
DEBUG:googleapiclient.discovery:URL being requested: GET https://gmail.googleapis.com/gmail/v1/users/me/profile?alt=json
INFO:root:Succesfully initializing email connection.
WARNING:googleapiclient.discovery_cache:file_cache is unavailable when using oauth2client >= 4.0.0 or google-auth
Traceback (most recent call last):
  File "C:\YOLOv5\yolov5\lib\site-packages\googleapiclient\discovery_cache\file_cache.py", line 33, in <module>
    from oauth2client.contrib.locked_file import LockedFile
ModuleNotFoundError: No module named 'oauth2client.contrib.locked_file'

During handling of the above exception, another exception occurred:

Traceback (most recent call last):
  File "C:\YOLOv5\yolov5\lib\site-packages\googleapiclient\discovery_cache\file_cache.py", line 37, in <module>
    from oauth2client.locked_file import LockedFile
ModuleNotFoundError: No module named 'oauth2client.locked_file'

During handling of the above exception, another exception occurred:

Traceback (most recent call last):
  File "C:\YOLOv5\yolov5\lib\site-packages\googleapiclient\discovery_cache\__init__.py", line 44, in autodetect
    from . import file_cache
  File "C:\YOLOv5\yolov5\lib\site-packages\googleapiclient\discovery_cache\file_cache.py", line 41, in <module>
    "file_cache is unavailable when using oauth2client >= 4.0.0 or google-auth"
ImportError: file_cache is unavailable when using oauth2client >= 4.0.0 or google-auth
DEBUG:googleapiclient.discovery:URL being requested: GET https://www.googleapis.com/discovery/v1/apis/gmail/v1/rest
DEBUG:googleapiclient.discovery:URL being requested: GET https://gmail.googleapis.com/gmail/v1/users/me/profile?alt=json
INFO:root:Succesfully initializing email connection.
INFO:root:Checking for new unread emails.
DEBUG:googleapiclient.discovery:URL being requested: GET https://gmail.googleapis.com/gmail/v1/users/me/threads?q=label%3AUNREAD&maxResults=25&alt=json
